<?xml version="1.0" ?>

<!--
# Copyright (c) 2022, ANTOBOT LTD.
# All rights reserved.

# THIS SOFTWARE IS PROVIDED BY THE COPYRIGHT HOLDERS AND CONTRIBUTORS
# "AS IS" AND ANY EXPRESS OR IMPLIED WARRANTIES, INCLUDING, BUT NOT
# LIMITED TO, THE IMPLIED WARRANTIES OF MERCHANTABILITY AND FITNESS FOR
# A PARTICULAR PURPOSE ARE DISCLAIMED. IN NO EVENT SHALL THE COPYRIGHT
# OWNER OR CONTRIBUTORS BE LIABLE FOR ANY DIRECT, INDIRECT, INCIDENTAL,
# SPECIAL, EXEMPLARY, OR CONSEQUENTIAL DAMAGES (INCLUDING, BUT NOT
# LIMITED TO, PROCUREMENT OF SUBSTITUTE GOODS OR SERVICES; LOSS OF USE,
# DATA, OR PROFITS; OR BUSINESS INTERRUPTION) HOWEVER CAUSED AND ON ANY
# THEORY OF LIABILITY, WHETHER IN CONTRACT, STRICT LIABILITY, OR TORT
# (INCLUDING NEGLIGENCE OR OTHERWISE) ARISING IN ANY WAY OUT OF THE USE
# OF THIS SOFTWARE, EVEN IF ADVISED OF THE POSSIBILITY OF SUCH DAMAGE.


# # # # # # # # # # # # # # # # # # # # # # # # # # # # # # # # # # # # # # # # # # # # # # # # # # # # # # # # # # # # # 

# # # Code Description:     URDF for AntoBot VP1

# Contact: william.eaton@antobot.ai

# # # #  # # # # # # # # # # # # # # # # # # # # # # # # # # # # # # # # # # # # # # # # # # # # # # # # # # # # # # # # #
-->



<robot name="antobot_vp1" xmlns:xacro="http://ros.org/wiki/xacro">

  <!-- Arguments -->
  <xacro:arg name="zed2_orientation"   default="left" />
  <xacro:property name="zed2_orientation"    value="$(arg zed2_orientation)" />

  <xacro:arg name="referenceLatitude"   default="51.7440620798811" />
  <xacro:property name="referenceLatitude"    value="$(arg referenceLatitude)" />
        
  <xacro:arg name="referenceLongitude"   default="0.472621240233513" />
  <xacro:property name="referenceLongitude"    value="$(arg referenceLongitude)" />   

  <!-- antobot -->
  <xacro:macro name="antobot_vp1">
    <xacro:property name="M_PI" value="3.1415926535897931" /> 
    
   
    <link name="base_link" />

    <link name="robot_base_link">
      <visual>
        <geometry>
          <mesh filename="package://antobot_vp1/meshes/chassis.dae" scale="1 1 1"/>
        </geometry>
        <origin xyz="0 0 0" rpy="0 0 0"/>
      </visual>
      <collision>
       <geometry>
          <mesh filename="package://antobot_vp1/meshes/chassis.dae" scale="1 1 1"/>
        </geometry>
        <origin xyz="0 0 0" rpy="0 0 0"/>
      </collision>
      <inertial>
        
        <origin xyz="0 0 0"/>
        <mass value="50"/>
        <inertia ixx="1.219624785" ixy="0.0" ixz="-0.984790199"
                 iyy="2.134816831" iyz="0.0"
                 izz="2.304314375" />
      </inertial>
    </link>
    
    <joint name="robot_base_joint" type="fixed">
      <origin xyz="0 0 0" rpy="0 0 0" />
      <parent link="base_link"/>
      <child link="robot_base_link" />
    </joint>

    <!-- left front -->

    <joint name="wheel_left_front_joint" type="continuous">
      <parent link="robot_base_link"/>
      <child link="wheel_left_front_link"/>
      <origin xyz="0.270673 0.258129 -0.237416" rpy="0 0 0"/>
      <axis xyz="0 1 0"/>
      <limit effort="300" velocity="100.0" />
    </joint>
  

    <link name="wheel_left_front_link">
      <visual>
        <geometry>
          <mesh filename="package://antobot_vp1/meshes/wheel.dae" scale="1 1 1" />          
        </geometry>
        <origin xyz="0 0 0" rpy="0 0 ${M_PI}"/>
      </visual>
      <collision>
        <geometry>
          <cylinder length="0.08" radius="0.16" />
        </geometry>
        <origin xyz="0 0.06 0" rpy="${M_PI/2} 0 0" />
      </collision>
      <inertial>
        <mass value="1.5" />
        <origin xyz="0 0 0" />
        <inertia ixx="0.009688532" ixy="0.0" ixz="0.0"
                 iyy="0.016578154" iyz="0.0"
                 izz="0.009688532" />
      </inertial>
    </link>  


    <!-- left rear -->

    <joint name="wheel_left_rear_joint" type="continuous">
      <parent link="robot_base_link"/>
      <child link="wheel_left_rear_link"/>
      <origin xyz="-0.284094 0.258129 -0.237416" rpy="0 0 0"/>
      <axis xyz="0 1 0"/>
      <limit effort="300" velocity="100.0" />
    </joint>
  

    <link name="wheel_left_rear_link">
      <visual>
        <geometry>
          <mesh filename="package://antobot_vp1/meshes/wheel.dae" scale="1 1 1" />      
        </geometry>
        <origin xyz="0 0 0" rpy="0 0 ${M_PI}"/>
      </visual>
      <collision>
        <geometry>
          <cylinder length="0.08" radius="0.16" />
        </geometry>
        <origin xyz="0 0.06 0" rpy="${M_PI/2} 0 0" />
      </collision>
      <inertial>
        <mass value="1.5" />
        <origin xyz="0 0 0" />
        <inertia ixx="0.009688532" ixy="0.0" ixz="0.0"
                 iyy="0.016578154" iyz="0.0"
                 izz="0.009688532" />
      </inertial>
    </link>

    <!-- right rear -->

    <joint name="wheel_right_rear_joint" type="continuous">
      <parent link="robot_base_link"/>
      <child link="wheel_right_rear_link"/>
      <origin xyz="-0.284094 -0.197866 -0.237416" rpy="0 0 0"/>
      <axis xyz="0 1 0"/>
      <limit effort="300" velocity="100.0" />
    </joint>
  

    <link name="wheel_right_rear_link">
      <visual>
        <geometry>
          <mesh filename="package://antobot_vp1/meshes/wheel.dae" scale="1 1 1" />      
        </geometry>
        <origin xyz="0 0 0" rpy="0 0 0"/>
      </visual>
      <collision>
        <geometry>
          <cylinder length="0.08" radius="0.16" />
        </geometry>
        <origin xyz="0 -0.06 0" rpy="${M_PI/2} 0 0" />
      </collision>
      <inertial>
        <mass value="1.5" />
        <origin xyz="0 0 0" />
        <inertia ixx="0.009688532" ixy="0.0" ixz="0.0"
                 iyy="0.016578154" iyz="0.0"
                 izz="0.009688532" />
      </inertial>
    </link>


    <!-- right front -->

    <joint name="wheel_right_front_joint" type="continuous">
      <parent link="robot_base_link"/>
      <child link="wheel_right_front_link"/>
      <origin xyz="0.270673 -0.197866 -0.237416" rpy="0 0 0"/>
      <axis xyz="0 1 0"/>
      <limit effort="300" velocity="100.0" />
    </joint>
  

    <link name="wheel_right_front_link">
      <visual>
        <geometry>
          <mesh filename="package://antobot_vp1/meshes/wheel.dae" scale="1 1 1" />      
        </geometry>
        <origin xyz="0 0 0" rpy="0 0 0"/>
      </visual>
      <collision>
        <geometry>
          <cylinder length="0.08" radius="0.16" />
        </geometry>
        <origin xyz="0 -0.06 0" rpy="${M_PI/2} 0 0" />
      </collision>
      <inertial>
        <mass value="1.5" />
        <origin xyz="0 0 0" />
        <inertia ixx="0.009688532" ixy="0.0" ixz="0.0"
                 iyy="0.016578154" iyz="0.0"
                 izz="0.009688532" />
      </inertial>
    </link>


    <gazebo reference="wheel_left_rear_link">
	    <mu1>0.4</mu1>
	    <mu2>0.4</mu2>
	    <kp>10000000.0</kp>
	    <kd>100.0</kd>
    </gazebo>

    <gazebo reference="wheel_left_front_link">
	    <mu1>0.4</mu1>
	    <mu2>0.4</mu2>
	    <kp>10000000.0</kp>
	    <kd>100.0</kd>
    </gazebo>

    <gazebo reference="wheel_right_front_link">
	    <mu1>0.4</mu1>
	    <mu2>0.4</mu2>
	    <kp>10000000.0</kp>
	    <kd>100.0</kd>
    </gazebo>

    <gazebo reference="wheel_right_rear_link">
	    <mu1>0.4</mu1>
	    <mu2>0.4</mu2>
	    <kp>10000000.0</kp>
	    <kd>100.0</kd>
    </gazebo>
 
      <transmission name="wheel_left_rear_trans" type="SimpleTransmission">
	<type>transmission_interface/SimpleTransmission</type>
	<actuator name="wheel_left_rear_motor">
		<mechanicalReduction>1</mechanicalReduction>
		<hardwareInterface>hardware_interface/VelocityJointInterface</hardwareInterface>
	</actuator>
	<joint name="wheel_left_rear_joint">
		<hardwareInterface>hardware_interface/VelocityJointInterface</hardwareInterface>
	</joint>
    </transmission>
    <transmission name="wheel_right_rear_trans" type="SimpleTransmission">
	<type>transmission_interface/SimpleTransmission</type>
	<actuator name="wheel_right_rear_motor">
		<mechanicalReduction>1</mechanicalReduction>
		<hardwareInterface>hardware_interface/VelocityJointInterface</hardwareInterface>
	</actuator>
	<joint name="wheel_right_rear_joint">
		<hardwareInterface>hardware_interface/VelocityJointInterface</hardwareInterface>
	</joint>
    </transmission>
    <transmission name="wheel_right_front_trans" type="SimpleTransmission">
	<type>transmission_interface/SimpleTransmission</type>
	<actuator name="wheel_right_front_motor">
		<mechanicalReduction>1</mechanicalReduction>
		<hardwareInterface>hardware_interface/VelocityJointInterface</hardwareInterface>
	</actuator>
	<joint name="wheel_right_front_joint">
		<hardwareInterface>hardware_interface/VelocityJointInterface</hardwareInterface>
	</joint>
    </transmission>
    <transmission name="wheel_left_front_trans" type="SimpleTransmission">
	<type>transmission_interface/SimpleTransmission</type>
	<actuator name="wheel_left_front_motor">
		<mechanicalReduction>1</mechanicalReduction>
		<hardwareInterface>hardware_interface/VelocityJointInterface</hardwareInterface>
	</actuator>
	<joint name="wheel_left_front_joint">
		<hardwareInterface>hardware_interface/VelocityJointInterface</hardwareInterface>
	</joint>
    </transmission>    

    <gazebo>
      <plugin name="gazebo_ros_control" filename="libgazebo_ros_control.so">
        <robotNamespace>/</robotNamespace>
      </plugin>
    </gazebo>

  <gazebo>
   <plugin name="p3d_base_controller" filename="libgazebo_ros_p3d.so">
    <alwaysOn>true</alwaysOn>
    <updateRate>10.0</updateRate>
    <bodyName>base_link</bodyName>
    <topicName>ground_truth/state</topicName>
    <gaussianNoise>0.0</gaussianNoise>
    <frameName>world</frameName>
    <xyzOffset>0 0 0</xyzOffset>
    <rpyOffset>0 0 0</rpyOffset>
   </plugin>
  </gazebo>

  <!-- front lidar -->
  
  <joint name="front_laser_joint" type="fixed">
      <parent link="robot_base_link"/>
      <child link="front_laser_frame"/>
      <origin xyz="0.59 0.03 0.3" rpy="0 0 ${M_PI}"/> <!-- orientation changed as per RPLidar A3 configuration-->
  </joint>

  <link name="front_laser_frame">
	<inertial>
	  <mass value="0.270" />
	  <origin xyz="0 0 0" rpy="0 0 0" />
	  <inertia ixx="2.632e-4" ixy="0" ixz="0" iyy="2.632e-4" iyz="0" izz="1.62e-4" />
	</inertial>
	
	<collision>
	  <origin xyz="0 0 0" rpy="0 0 0" />
	  <geometry>
      <mesh filename="package://antobot_vp1/meshes/rpLidar.dae" scale="1 1 1" />      
	  </geometry>
	</collision>
  <visual>
    <geometry>
      <mesh filename="package://antobot_vp1/meshes/rpLidar.dae" scale="1 1 1" />      
    </geometry>
    <origin xyz="0 0 0" rpy="0 0 0"/>
  </visual>

  </link>

  <gazebo reference="front_laser_frame">
    <sensor type="ray" name="head_front_laser_sensor">
      <pose>0 0 0 0 0 0</pose>
      <visualize>false</visualize>
      <update_rate>10</update_rate>
      <ray>
        <scan>
          <horizontal>
            <samples>1080</samples>
             <!--<resolution>0.25</resolution>-->

            <min_angle>-3.1415</min_angle> 
            <max_angle>3.1415</max_angle> 
          </horizontal>
        </scan>
        <range>
          <min>0.10</min>
          <max>30</max>
          <resolution>0.01</resolution>
        </range>
        <noise>
          <type>gaussian</type>
     
          <mean>0.0</mean>
          <stddev>0.01</stddev>
        </noise>
      </ray>
      <plugin name="gazebo_ros_head_front_laser_controller" filename="libgazebo_ros_laser.so">
        <topicName>scan</topicName>
        <frameName>front_laser_frame</frameName>
      </plugin>
    </sensor>
  </gazebo> 

  <!-- /front lidar -->

  <!-- gps -->

  <joint name="gps_joint" type="fixed">
      <parent link="robot_base_link"/>
      <child link="gps_frame"/>
      <origin xyz="0.542833 0.029782 0.494249" rpy="0 0 0"/>
  </joint>

  <link name="gps_frame">
	<inertial>
	  <mass value="0.270" />
	  <origin xyz="0 0 0" rpy="0 0 0" />
	  <inertia ixx="2.632e-4" ixy="0" ixz="0" iyy="2.632e-4" iyz="0" izz="1.62e-4" />
	</inertial>
	
  </link>




  <gazebo>
    <plugin name="gazebo_ros_gps" filename="libhector_gazebo_ros_gps.so" >
        <updateRate>4.0</updateRate>
        <bodyName>gps_frame</bodyName>
        <frameId>gps_frame</frameId>
        <!-- <topicName>/ant_rtk</topicName> -->
        <topicName>/am_gps_urcu</topicName>
        <velocityTopicName>/am_gps_vel</velocityTopicName>
        <referenceLatitude>${referenceLatitude}</referenceLatitude>
        <referenceLongitude>${referenceLongitude}</referenceLongitude>
        <!--<referenceLatitude>51.7440620798811</referenceLatitude> 
        <referenceLongitude>0.472621240233513</referenceLongitude> --> <!-- courtyard -->
        <!--<referenceLatitude>51.59584877</referenceLatitude>
        <referenceLongitude>-0.97799757</referenceLongitude> -->  <!-- vineyard-->
        <!-- 
        <topicName>/am_m8p_rtkgnss/fix</topicName>
        <velocityTopicName>/am_m8p_rtkgnss_vel</velocityTopicName>
        <referenceLatitude>51.51232213921896</referenceLatitude>
        <referenceLongitude>-0.1276964444279933</referenceLongitude>
         -->
        <referenceHeading>90</referenceHeading>
        <referenceAltitude>10</referenceAltitude>
        <offset>0 0 0</offset>
 
	<drift>0.0 0.0 0.0</drift>
	<gaussianNoise>0.01 0.01 0.01</gaussianNoise>
	<velocityDrift>0 0 0</velocityDrift>
	<velocityGaussianNoise>0.5 0.5 0.5</velocityGaussianNoise>
    </plugin>
  </gazebo>
  
  <!-- gps 2 (back) -->
  <!--<joint name="gps_joint_back" type="fixed">
      <parent link="robot_base_link"/>
      <child link="gps_frame_back"/>
      <origin xyz="-0.542833 0.029782 0.494249" rpy="0 0 0"/>-->
      <!--origin xyz="0.468 1.305 -0.00186" rpy="${M_PI/2} 0 ${M_PI}"/-->
  <!--</joint>

  <link name="gps_frame_back">
	<inertial>
	  <mass value="0.270" />
	  <origin xyz="0 0 0" rpy="0 0 0" />
	  <inertia ixx="2.632e-4" ixy="0" ixz="0" iyy="2.632e-4" iyz="0" izz="1.62e-4" />
	</inertial>
  </link>

  <gazebo>
    <plugin name="gazebo_ros_gps_back" filename="libhector_gazebo_ros_gps.so">
        <updateRate>4.0</updateRate>
        <bodyName>gps_frame_back</bodyName>
        <frameId>gps_frame_back</frameId>
        <topicName>/gps_back/fix</topicName>
        <velocityTopicName>/gps_back/fix_velocity</velocityTopicName>
        <referenceLatitude>${referenceLatitude}</referenceLatitude>
        <referenceLongitude>${referenceLongitude}</referenceLongitude>-->
        <!--<referenceLatitude>51.59709771356923</referenceLatitude>
        <referenceLongitude>-0.978617196410762</referenceLongitude> -->  <!--vineyard worked with worked coordinates -->
        <!--<referenceLatitude>51.59727692574319</referenceLatitude>
        <referenceLongitude>-0.978406641426352</referenceLongitude> -->
        <!--<referenceHeading>90</referenceHeading>
        <referenceAltitude>10</referenceAltitude>
        <offset>0 0 0</offset>
 
	<drift>0.0 0.0 0.0</drift>
	<gaussianNoise>0.01 0.01 0.01</gaussianNoise>
	<velocityDrift>0 0 0</velocityDrift>
	<velocityGaussianNoise>0.01 0.01 0.01</velocityGaussianNoise>
    </plugin>
  </gazebo>-->
  


  <!-- imu -->

  <joint name="imu_joint" type="fixed">
      <parent link="base_link"/>
      <child link="imu_frame"/>
      <origin xyz="0.0 0.0 0.0" rpy="0 0 0"/>
      <!-- <origin xyz="0.081 -0.001 0.000" rpy="0 ${M_PI/2} ${-M_PI/2}"/> -->
  </joint>

  <link name="imu_frame">
	<inertial>
	  <mass value="0.270" />
	  <origin xyz="0 0 0" rpy="0 0 0" />
	  <inertia ixx="2.632e-4" ixy="0" ixz="0" iyy="2.632e-4" iyz="0" izz="1.62e-4" />
	</inertial>
  </link> 
  <gazebo>
    <plugin name="imu_plugin" filename="libgazebo_ros_imu.so">
      <alwaysOn>true</alwaysOn>
      <bodyName>imu_frame</bodyName>
      <topicName>/imu/data</topicName>
      <serviceName>imu_service</serviceName>
      <gaussianNoise>0.0</gaussianNoise>
      <updateRate>20.0</updateRate>
    </plugin>
  </gazebo>


  <!-- ZED camera -->
  






  <!-- Position the camera on the front mast -->

  <!-- Forward facing camera - within Robot head1 -->
  <xacro:if value="${zed2_orientation == 'front'}">
    <xacro:property name="cameraXYZ" value="0.641 0.03 0.127" />
    <xacro:property name="cameraRPY" value="0 0 0" />

    <!-- Front side mount -->
    <joint name="zed2_mount_joint" type="fixed">
      <parent link="robot_base_link"/>
      <child link="zed2_mount_link"/>
      <origin xyz="0.55 0.04 0.36" rpy="0 0 0"/>
    </joint>

    <link name="zed2_mount_link">
      <visual>
        <geometry>
          <mesh filename="package://antobot_vp1/meshes/zedMountLeft.dae" scale="1 1 1" />      
        </geometry>
        <origin xyz="0 0 0" rpy="0 0 0"/>
      </visual>
      <collision>
        <geometry>
          <mesh filename="package://antobot_vp1/meshes/zedMountLeft.dae" scale="1 1 1" />      
        </geometry>
        <origin xyz="0 0 0" rpy="0 0 0"/>
      </collision>
      <inertial>
        <mass value="0.05" />
        <origin xyz="0 0 0" rpy="0 0 0" />
        <inertia ixx="2.632e-4" ixy="0" ixz="0" iyy="2.632e-4" iyz="0" izz="1.62e-4" />
      </inertial>
    </link>
  </xacro:if>





  <!-- Left facing camera -->
  <xacro:if value="${zed2_orientation == 'left'}">
    <xacro:property name="cameraXYZ" value="0.56 0.13 0.375" />
    <xacro:property name="cameraRPY" value="0 0 ${M_PI/2}" />

    <!-- Left side mount -->
    <joint name="zed2_mount_joint" type="fixed">
      <parent link="robot_base_link"/>
      <child link="zed2_mount_link"/>
      <origin xyz="0.55 0.04 0.36" rpy="0 0 0"/>
    </joint>

    <link name="zed2_mount_link">
      <visual>
        <geometry>
          <mesh filename="package://antobot_vp1/meshes/zedMountLeft.dae" scale="1 1 1" />      
        </geometry>
        <origin xyz="0 0 0" rpy="0 0 0"/>
      </visual>
      <collision>
        <geometry>
          <mesh filename="package://antobot_vp1/meshes/zedMountLeft.dae" scale="1 1 1" />      
        </geometry>
        <origin xyz="0 0 0" rpy="0 0 0"/>
      </collision>
      <inertial>
        <mass value="0.05" />
        <origin xyz="0 0 0" rpy="0 0 0" />
        <inertia ixx="2.632e-4" ixy="0" ixz="0" iyy="2.632e-4" iyz="0" izz="1.62e-4" />
      </inertial>
    </link>

  </xacro:if>



  <!-- Right facing camera -->
  <xacro:if value="${zed2_orientation == 'right'}">
    <xacro:property name="cameraXYZ" value="0.56 -0.07 0.375" />
    <xacro:property name="cameraRPY" value="0 0 ${-M_PI/2}" />
    
    <!-- Right side mount -->
    <joint name="zed2_mount_joint" type="fixed">
      <parent link="robot_base_link"/>
      <child link="zed2_mount_link"/>
      <origin xyz="0.55 0.02 0.36" rpy="0 0 0"/>
    </joint>

    <link name="zed2_mount_link">
      <visual>
        <geometry>
          <mesh filename="package://antobot_vp1/meshes/zedMountRight.dae" scale="1 1 1" />      
        </geometry>
        <origin xyz="0 0 0" rpy="0 0 0"/>
      </visual>
      <collision>
        <geometry>
          <mesh filename="package://antobot_vp1/meshes/zedMountRight.dae" scale="1 1 1" />      
        </geometry>
        <origin xyz="0 0 0" rpy="0 0 0"/>
      </collision>
      <inertial>
        <mass value="0.05" />
        <origin xyz="0 0 0" rpy="0 0 0" />
        <inertia ixx="2.632e-4" ixy="0" ixz="0" iyy="2.632e-4" iyz="0" izz="1.62e-4" />
      </inertial>
    </link>

  </xacro:if>

  <!-- zed camera  -->


  <joint name="zed2_joint" type="fixed">
      <parent link="robot_base_link"/>
      <child link="zed2_front_camera_center"/>
      <origin xyz="0.53 0.05 0.0" rpy="0 0 0"/>
  </joint>

  <!-- For scouting left -->
  <joint name="scouting_joint_left" type="fixed">
    <origin xyz="0.641 0.03 0.127" rpy="-${pi/2} 0.0 0.0"/>
    <parent link="robot_base_link"/>
    <child link="scouting_frame_left"/>
  </joint>

  <link name="scouting_frame_left"/>

  <!-- For scouting right -->
  <joint name="scouting_joint_right" type="fixed">
    <origin xyz="0.641 0.03 0.127" rpy="${pi/2} ${pi} 0.0"/>
    <parent link="robot_base_link"/>
    <child link="scouting_frame_right"/>
  </joint>

  <link name="scouting_frame_right"/>
  
  <xacro:include filename="$(find antobot_vp1)/urdf/zed2.urdf.xacro"/>
  <xacro:zed2_front link_prefix='' 
              joint_prefix=''/>

  <xacro:zed2_front_gazebo robot_ns=''/>
  

  <!-- Back facing camera -->
  
  <joint name="zed2_joint_back" type="fixed">
      <parent link="robot_base_link"/>
      <child link="zed2_back_camera_center"/>
      <origin xyz="0.53 -0.05 0.375" rpy="0 0 ${M_PI}"/>
  </joint>
  
  <xacro:include filename="$(find antobot_vp1)/urdf/zed2_back.urdf.xacro"/>
  <xacro:zed2_back link_prefix='' 
                   joint_prefix=''/>

  <xacro:zed2_back_gazebo robot_ns=''/>
  

  </xacro:macro>
  <xacro:antobot_vp1/>
</robot>
